<?xml version="1.0" ?>
<robot name="b3m_example">
  <link name="world"/>
  <link name="base_link">
    <visual>
      <geometry>
        <box size="0.043 0.032 0.0325"/>
      </geometry>
      <material name="servo_color">
        <color rgba="0.9 0.9 0.9 1"/>
      </material>
    </visual>
    <collision>
      <origin xyz="0.0 0.0 0.0" rpy="0 0 0"/>
      <geometry>
        <box size="0.043 0.032 0.0325"/>
      </geometry>
    </collision>
    <inertial>
      <origin xyz="0.0 0.0 0.0" rpy="0 0 0"/>
      <inertia ixx="0.001" ixy="0" ixz="0" iyy="0.001" iyz="0" izz="0.001"/>
      <mass value="0.01"/>
    </inertial>
  </link>
  <link name="joint1_link">
    <visual>
      <geometry>
        <cylinder radius="0.0105" length="0.0055"/>
      </geometry>
      <material name="hone_color">
        <color rgba="0.6 0.6 0.6 1"/>
      </material>
    </visual>
    <collision>
      <origin xyz="0.0 0.0 0.0" rpy="0 0 0"/>
      <geometry>
        <cylinder radius="0.0105" length="0.0055"/>
      </geometry>
    </collision>
    <inertial>
      <origin xyz="0.0 0.0 0.0" rpy="0 0 0"/>
      <inertia ixx="0.001" ixy="0" ixz="0" iyy="0.001" iyz="0" izz="0.001"/>
      <mass value="0.01"/>
    </inertial>
  </link>
  <link name="bar_link">
    <visual>
      <geometry>
        <box size="0.050 0.001 0.006"/>
      </geometry>
      <material name="bar_color">
        <color rgba="0.2 0.8 0.2 1"/>
      </material>
    </visual>
    <collision>
      <origin xyz="0.0 0.0 0.0" rpy="0 0 0"/>
      <geometry>
        <box size="0.050 0.001 0.006"/>
      </geometry>
    </collision>
    <inertial>
      <origin xyz="0.0 0.0 0.0" rpy="0 0 0"/>
      <inertia ixx="0.001" ixy="0" ixz="0" iyy="0.001" iyz="0" izz="0.001"/>
      <mass value="0.01"/>
    </inertial>
  </link>
  <link name="joint2_link">
    <visual>
      <geometry>
        <box size="0.03 0.002 0.03"/>
      </geometry>
      <material name="joint2_color">
        <color rgba="0.8 0.2 0.2 1"/>
      </material>
    </visual>
    <collision>
      <origin xyz="0.0 0.0 0.0" rpy="0 0 0"/>
      <geometry>
        <box size="0.03 0.002 0.03"/>
      </geometry>
    </collision>
    <inertial>
      <origin xyz="0.0 0.0 0.0" rpy="0 0 0"/>
      <inertia ixx="0.001" ixy="0" ixz="0" iyy="0.001" iyz="0" izz="0.001"/>
      <mass value="0.01"/>
    </inertial>
  </link>

  <joint name="base_joint" type="fixed">
    <parent link="world" />
    <child link="base_link" />
    <origin xyz="-0.012 0.0 0.01625" rpy="0 0 0"/>
  </joint>

  <joint name="joint1" type="revolute">
    <parent link="base_link" />
    <child link="joint1_link" />
    <origin xyz="0.0095 0.0 0.01625" rpy="0 0 0"/>
    <limit lower="-2.79" upper="2.79" effort="4.0" velocity="4.7"/>
    <axis xyz="0 0 1"/>
  </joint>

  <joint name="bar_joint" type="fixed">
    <parent link="joint1_link" />
    <child link="bar_link" />
    <origin xyz="0.015 0.0 0.00275" rpy="0 0 0"/>
  </joint>

  <joint name="joint2" type="revolute">
    <parent link="bar_link" />
    <child link="joint2_link" />
    <origin xyz="0.025 0.0 0.0" rpy="0 0 0"/>
    <limit lower="-2.79" upper="2.79" effort="4.0" velocity="4.7"/>
    <axis xyz="0 1 0"/>
  </joint>

  <gazebo>
    <plugin name="gazebo_ros_control" filename="libgazebo_ros_control.so">
      <robotNamespace>/b3m</robotNamespace>
      <robotSimType>gazebo_ros_control/DefaultRobotHWSim</robotSimType>
      <legacyModeNS>false</legacyModeNS>
    </plugin>
  </gazebo>

  <transmission name="trans1">
    <type>transmission_interface/SimpleTransmission</type>
    <joint name="joint1">
      <hardwareInterface>hardware_interface/PositionJointInterface</hardwareInterface>
    </joint>
    <actuator name="joint1_motor">
      <hardwareInterface>hardware_interface/PositionJointInterface</hardwareInterface>
      <mechanicalReduction>1</mechanicalReduction>
    </actuator>
  </transmission>
  <transmission name="trans2">
    <type>transmission_interface/SimpleTransmission</type>
    <joint name="joint2">
      <hardwareInterface>hardware_interface/PositionJointInterface</hardwareInterface>
    </joint>
    <actuator name="joint2_motor">
      <hardwareInterface>hardware_interface/PositionJointInterface</hardwareInterface>
      <mechanicalReduction>1</mechanicalReduction>
    </actuator>
  </transmission>

  <gazebo reference="base_link">
    <selfCollide>false</selfCollide>
    <material>Gazebo/White</material>
  </gazebo>
  <gazebo reference="joint1_link">
    <selfCollide>false</selfCollide>
    <material>Gazebo/Gray</material>
  </gazebo>
  <gazebo reference="bar_link">
    <selfCollide>false</selfCollide>
    <material>Gazebo/Green</material>
  </gazebo>
  <gazebo reference="joint2_link">
    <selfCollide>false</selfCollide>
    <material>Gazebo/Red</material>
  </gazebo>

</robot>

